#the try block will generate an exeception,
#because x is not defined

try:
    print(x)
except:
    print("an exception occurred")
    